<?xml version="1.0" ?>
<!-- =================================================================================== -->
<!-- |    This document was autogenerated by xacro from ../robots/hyq.urdf.xacro       | -->
<!-- |    EDITING THIS FILE BY HAND IS NOT RECOMMENDED                                 | -->
<!-- =================================================================================== -->
<robot name="hyq" xmlns:xacro="http://www.ros.org/wiki/xacro">
  <!-- The following included files set up definitions of parts of the robot body -->
  <!-- HyQ trunk -->
  <!-- HyQ legs -->
  <!-- HyQ sensors -->
  <!--
	<xacro:include filename="$(find hyq_description)/urdfs/sensors/microstrain_3dmgx325_imu.urdf.xacro"/>
	<xacro:include filename="$(find hyq_description)/urdfs/sensors/asus_xtion.urdf.xacro"/>
	<xacro:include filename="$(find hyq_description)/urdfs/sensors/velodyne.urdf.xacro"/>
	<xacro:include filename="$(find hyq_description)/urdfs/sensors/kinect.urdf.xacro"/>
	<xacro:include filename="$(find hyq_description)/urdfs/sensors/ptu_d46.urdf.xacro"/>
	<xacro:include filename="$(find hyq_description)/urdfs/sensors/bumblebee.urdf.xacro"/>
	<xacro:include filename="$(find hyq_description)/urdfs/sensors/vislab_3dve.urdf.xacro"/>
-->
  <!-- generic simulator_gazebo plugins for starting mechanism control, ros time -->
  <!--
	<xacro:include filename="$(find hyq_description)/gazebo/gazebo.urdf.xacro"/>
-->
  <!-- Now we can start using the macros included above to define the actual HyQ -->
  <!-- The first use of a macro. This one was defined in trunk.urdf.xacro above.
A macro like this will expand to a set of link and joint definitions, and to additional
Gazebo-related extensions (sensor plugins, etc). The macro takes an argument, name,
that equals "base", and uses it to generate names for its component links and joints
(e.g., base_link). The included origin block is also an argument to the macro. By convention,
the origin block defines where the component is w.r.t its parent (in this case the parent
is the world frame). For more, see http://www.ros.org/wiki/xacro -->
  <!-- body -->
  <!-- trunk -->
  <joint name="floating_base" type="fixed">
    <origin rpy="0 0 0" xyz="0 0 0"/>
    <parent link="base_link"/>
    <child link="trunk"/>
  </joint>
  <link name="base_link">
 <!--   <visual>
      <geometry>
        <cylinder length="0.01" radius="0.01"/>
      </geometry>
    </visual> -->
  </link>
  <link name="trunk">
    <inertial>
      <origin xyz="-0.02758 -2.3319e-05 0.03103"/>
      <mass value="50.24"/>
      <inertia ixx="0.97322" ixy="-0.0067362" ixz="0.1681" iyy="5.0487" iyz="-0.0060307" izz="5.283"/>
    </inertial>
    <visual>
      <geometry>
        <mesh filename="package://hyq_description/meshes/trunk/trunk.dae" scale="1 1 1"/>
      </geometry>
    </visual>
    <collision>
      <geometry>
        <mesh filename="package://hyq_description/meshes/trunk/trunk.dae" scale="1 1 1"/>
      </geometry>
    </collision>
  </link>
  <gazebo reference="trunk">
    <mu1>0.9</mu1>
    <mu2>0.9</mu2>
  </gazebo>
  <!-- LF leg -->
  <joint name="lf_haa_joint" type="revolute">
    <origin rpy="0 1.57079632679 3.14159265359" xyz="0.3735 0.207 0"/>
    <parent link="trunk"/>
    <child link="lf_hipassembly"/>
    <axis xyz="0 0 1"/>
    <limit effort="150.0" lower="-1.2217304764" upper="0.523598775598" velocity="12.0"/>
    <dynamics damping="0.1" friction="0"/>
    <safety_controller k_position="100" k_velocity="100" soft_lower_limit="-10" soft_upper_limit="12.45"/>
  </joint>
  <joint name="lf_hfe_joint" type="revolute">
    <origin rpy="1.57079632679 0 0" xyz="0.082 0 0"/>
    <parent link="lf_hipassembly"/>
    <child link="lf_upperleg"/>
    <axis xyz="0 0 1"/>
    <limit effort="150.0" lower="-0.872664625997" upper="1.2217304764" velocity="12.0"/>
    <dynamics damping="0.1" friction="0"/>
    <safety_controller k_position="100" k_velocity="100" soft_lower_limit="-10" soft_upper_limit="12.45"/>
  </joint>
  <joint name="lf_kfe_joint" type="revolute">
    <origin rpy="0 0 0" xyz="0.35 0 0"/>
    <parent link="lf_upperleg"/>
    <child link="lf_lowerleg"/>
    <axis xyz="0 0 1"/>
    <limit effort="150.0" lower="-2.44346095279" upper="-0.349065850399" velocity="12.0"/>
    <dynamics damping="0.1" friction="0"/>
    <safety_controller k_position="100" k_velocity="100" soft_lower_limit="-10" soft_upper_limit="12.45"/>
    <!-- Foot joint -->
  </joint>
  <joint name="lf_foot_joint" type="fixed">
    <origin rpy="1.57079632679 0 -1.57079632679" xyz="0.35 0 0"/>
    <parent link="lf_lowerleg"/>
    <child link="lf_foot"/>
  </joint>
  <link name="lf_hipassembly">
    <inertial>
      <origin xyz="0.04263         0.0         0.16931"/>
      <mass value="2.93"/>
      <inertia ixx="0.134705" ixy="3.6e-05" ixz="0.022734" iyy="0.144171" iyz="5.1e-05" izz="0.011033"/>
    </inertial>
    <visual>
      <origin rpy="0.0 0 0" xyz="0 0 0"/>
      <geometry>
        <mesh filename="package://hyq_description/meshes/leg/hipassembly.dae" scale="1 1 1"/>
      </geometry>
    </visual>
    <collision>
      <origin rpy="0.0 0 0" xyz="0 0 0"/>
      <geometry>
        <mesh filename="package://hyq_description/meshes/leg/hipassembly.dae" scale="1 1 1"/>
      </geometry>
    </collision>
  </link>
  <link name="lf_upperleg">
    <inertial>
      <origin xyz="0.15074 0.02625 0.0"/>
      <mass value="2.638"/>
      <inertia ixx="0.005495" ixy="-0.007418" ixz="-0.000102" iyy="0.087136" iyz="-2.1e-05" izz="0.089871"/>
    </inertial>
    <visual>
      <origin rpy="0.0 0 0" xyz="0 0 0"/>
      <geometry>
        <mesh filename="package://hyq_description/meshes/leg/upperleg.dae" scale="1 1 1"/>
      </geometry>
    </visual>
    <collision>
      <origin rpy="0.0 0 0" xyz="0 0 0"/>
      <geometry>
        <mesh filename="package://hyq_description/meshes/leg/upperleg.dae" scale="1 1 1"/>
      </geometry>
    </collision>
  </link>
  <link name="lf_lowerleg">
    <inertial>
      <origin xyz="0.1254 5e-05 -0.0001"/>
      <mass value="0.881"/>
      <inertia ixx="0.000468" ixy="0.0" ixz="0.0" iyy="0.026409" iyz="0.0" izz="0.026181"/>
    </inertial>
    <visual>
      <geometry>
        <mesh filename="package://hyq_description/meshes/leg/lowerleg.dae" scale="1 1 1"/>
      </geometry>
      <material name="white"/>
    </visual>
    <collision>
      <geometry>
        <mesh filename="package://hyq_description/meshes/leg/lowerlegreduced.dae" scale="1 1 1"/>
      </geometry>
    </collision>
  </link>
  <link name="lf_foot">
    <inertial>
      <origin xyz="0 0 0"/>
      <mass value="0.01"/>
      <inertia ixx="0.0" ixy="0.0" ixz="0.0" iyy="0.0" iyz="0.0" izz="0.0"/>
    </inertial>
    <visual>
				<origin xyz="0.0 0.0 0.0" rpy="0.0 0.0 0.0"/>
				<geometry>
					<sphere radius="0.021"/>
				</geometry>
			</visual>
    <collision>
      <origin rpy="0 0 0" xyz="0 0 0"/>
      <geometry>
        <sphere radius="0.02175"/>
      </geometry>
    </collision>
  </link>
  <transmission name="lf_haa_trans">
    <type>transmission_interface/SimpleTransmission</type>
    <joint name="lf_haa_joint">
      <hardwareInterface>EffortJointInterface</hardwareInterface>
    </joint>
    <actuator name="lf_haa_motor">
      <hardwareInterface>EffortJointInterface</hardwareInterface>
      <mechanicalReduction>1</mechanicalReduction>
    </actuator>
  </transmission>
  <transmission name="lf_hfe_upper_trans">
    <type>transmission_interface/SimpleTransmission</type>
    <joint name="lf_hfe_joint">
      <hardwareInterface>EffortJointInterface</hardwareInterface>
    </joint>
    <actuator name="lf_hfe_motor">
      <hardwareInterface>EffortJointInterface</hardwareInterface>
      <mechanicalReduction>1</mechanicalReduction>
    </actuator>
  </transmission>
  <transmission name="lf_kfe_trans">
    <type>transmission_interface/SimpleTransmission</type>
    <joint name="lf_kfe_joint">
      <hardwareInterface>EffortJointInterface</hardwareInterface>
    </joint>
    <actuator name="lf_kfe_motor">
      <hardwareInterface>EffortJointInterface</hardwareInterface>
      <mechanicalReduction>1</mechanicalReduction>
    </actuator>
  </transmission>
  <gazebo reference="lf_lowerleg">
    <kp>1000000.0</kp>
    <kd>100.0</kd>
    <mu1>1.5</mu1>
    <mu2>1.5</mu2>
    <fdir1>1 0 0</fdir1>
    <maxVel>1.0</maxVel>
    <minDepth>0.00</minDepth>
  </gazebo>
  <!-- RF leg -->
  <joint name="rf_haa_joint" type="revolute">
    <origin rpy="0 1.57079632679 0" xyz="0.3735 -0.207 0"/>
    <parent link="trunk"/>
    <child link="rf_hipassembly"/>
    <axis xyz="0 0 1"/>
    <limit effort="150.0" lower="-1.2217304764" upper="0.523598775598" velocity="12.0"/>
    <dynamics damping="0.1" friction="0"/>
    <safety_controller k_position="100" k_velocity="100" soft_lower_limit="-10" soft_upper_limit="12.45"/>
  </joint>
  <joint name="rf_hfe_joint" type="revolute">
    <origin rpy="-1.57079632679 0 0" xyz="0.082 0 0"/>
    <parent link="rf_hipassembly"/>
    <child link="rf_upperleg"/>
    <axis xyz="0 0 1"/>
    <limit effort="150.0" lower="-0.872664625997" upper="1.2217304764" velocity="12.0"/>
    <dynamics damping="0.1" friction="0"/>
    <safety_controller k_position="100" k_velocity="100" soft_lower_limit="-10" soft_upper_limit="12.45"/>
  </joint>
  <joint name="rf_kfe_joint" type="revolute">
    <origin rpy="0 0 0" xyz="0.35 0 0"/>
    <parent link="rf_upperleg"/>
    <child link="rf_lowerleg"/>
    <axis xyz="0 0 1"/>
    <limit effort="150.0" lower="-2.44346095279" upper="-0.349065850399" velocity="12.0"/>
    <dynamics damping="0.1" friction="0"/>
    <safety_controller k_position="100" k_velocity="100" soft_lower_limit="-10" soft_upper_limit="12.45"/>
    <!-- Foot joint -->
  </joint>
  <joint name="rf_foot_joint" type="fixed">
    <origin rpy="1.57079632679 0 -1.57079632679" xyz="0.35 0 0"/>
    <parent link="rf_lowerleg"/>
    <child link="rf_foot"/>
  </joint>
  <link name="rf_hipassembly">
    <inertial>
      <origin xyz="0.04263         -0.0         -0.16931"/>
      <mass value="2.93"/>
      <inertia ixx="0.134705" ixy="-3.6e-05" ixz="-0.022734" iyy="0.144171" iyz="5.1e-05" izz="0.011033"/>
    </inertial>
    <visual>
      <origin rpy="3.14159265359 0 0" xyz="0 0 0"/>
      <geometry>
        <mesh filename="package://hyq_description/meshes/leg/hipassembly.dae" scale="1 1 1"/>
      </geometry>
    </visual>
    <collision>
      <origin rpy="3.14159265359 0 0" xyz="0 0 0"/>
      <geometry>
        <mesh filename="package://hyq_description/meshes/leg/hipassembly.dae" scale="1 1 1"/>
      </geometry>
    </collision>
  </link>
  <link name="rf_upperleg">
    <inertial>
      <origin xyz="0.15074 -0.02625 0.0"/>
      <mass value="2.638"/>
      <inertia ixx="0.005495" ixy="-0.007418" ixz="-0.000102" iyy="0.087136" iyz="-2.1e-05" izz="0.089871"/>
    </inertial>
    <visual>
      <origin rpy="0.0 0 0" xyz="0 0 0"/>
      <geometry>
        <mesh filename="package://hyq_description/meshes/leg/upperleg.dae" scale="1 1 1"/>
      </geometry>
    </visual>
    <collision>
      <origin rpy="0.0 0 0" xyz="0 0 0"/>
      <geometry>
        <mesh filename="package://hyq_description/meshes/leg/upperleg.dae" scale="1 1 1"/>
      </geometry>
    </collision>
  </link>
  <link name="rf_lowerleg">
    <inertial>
      <origin xyz="0.1254 5e-05 -0.0001"/>
      <mass value="0.881"/>
      <inertia ixx="0.000468" ixy="0.0" ixz="0.0" iyy="0.026409" iyz="0.0" izz="0.026181"/>
    </inertial>
    <visual>
      <geometry>
        <mesh filename="package://hyq_description/meshes/leg/lowerleg.dae" scale="1 1 1"/>
      </geometry>
      <material name="white"/>
    </visual>
    <collision>
      <geometry>
        <mesh filename="package://hyq_description/meshes/leg/lowerlegreduced.dae" scale="1 1 1"/>
      </geometry>
    </collision>
  </link>
  <link name="rf_foot">
    <inertial>
      <origin xyz="0 0 0"/>
      <mass value="0.01"/>
      <inertia ixx="0.0" ixy="0.0" ixz="0.0" iyy="0.0" iyz="0.0" izz="0.0"/>
    </inertial>
    <visual>
				<origin xyz="0.0 0.0 0.0" rpy="0.0 0.0 0.0"/>
				<geometry>
					<sphere radius="0.021"/>
				</geometry>
			</visual>
    <collision>
      <origin rpy="0 0 0" xyz="0 0 0"/>
      <geometry>
        <sphere radius="0.02175"/>
      </geometry>
    </collision>
  </link>
  <transmission name="rf_haa_trans">
    <type>transmission_interface/SimpleTransmission</type>
    <joint name="rf_haa_joint">
      <hardwareInterface>EffortJointInterface</hardwareInterface>
    </joint>
    <actuator name="rf_haa_motor">
      <hardwareInterface>EffortJointInterface</hardwareInterface>
      <mechanicalReduction>1</mechanicalReduction>
    </actuator>
  </transmission>
  <transmission name="rf_hfe_upper_trans">
    <type>transmission_interface/SimpleTransmission</type>
    <joint name="rf_hfe_joint">
      <hardwareInterface>EffortJointInterface</hardwareInterface>
    </joint>
    <actuator name="rf_hfe_motor">
      <hardwareInterface>EffortJointInterface</hardwareInterface>
      <mechanicalReduction>1</mechanicalReduction>
    </actuator>
  </transmission>
  <transmission name="rf_kfe_trans">
    <type>transmission_interface/SimpleTransmission</type>
    <joint name="rf_kfe_joint">
      <hardwareInterface>EffortJointInterface</hardwareInterface>
    </joint>
    <actuator name="rf_kfe_motor">
      <hardwareInterface>EffortJointInterface</hardwareInterface>
      <mechanicalReduction>1</mechanicalReduction>
    </actuator>
  </transmission>
  <gazebo reference="rf_lowerleg">
    <kp>1000000.0</kp>
    <kd>100.0</kd>
    <mu1>1.5</mu1>
    <mu2>1.5</mu2>
    <fdir1>1 0 0</fdir1>
    <maxVel>1.0</maxVel>
    <minDepth>0.00</minDepth>
  </gazebo>
  <!-- LH leg -->
  <joint name="lh_haa_joint" type="revolute">
    <origin rpy="0 1.57079632679 3.14159265359" xyz="-0.3735 0.207 0"/>
    <parent link="trunk"/>
    <child link="lh_hipassembly"/>
    <axis xyz="0 0 1"/>
    <limit effort="150.0" lower="-1.2217304764" upper="0.523598775598" velocity="12.0"/>
    <dynamics damping="0.1" friction="0"/>
    <safety_controller k_position="100" k_velocity="100" soft_lower_limit="-10" soft_upper_limit="12.45"/>
  </joint>
  <joint name="lh_hfe_joint" type="revolute">
    <origin rpy="1.57079632679 0 0" xyz="0.082 0 0"/>
    <parent link="lh_hipassembly"/>
    <child link="lh_upperleg"/>
    <axis xyz="0 0 1"/>
    <limit effort="150.0" lower="-1.2217304764" upper="0.872664625997" velocity="12.0"/>
    <dynamics damping="0.1" friction="0"/>
    <safety_controller k_position="100" k_velocity="100" soft_lower_limit="-10" soft_upper_limit="12.45"/>
  </joint>
  <joint name="lh_kfe_joint" type="revolute">
    <origin rpy="0 0 0" xyz="0.35 0 0"/>
    <parent link="lh_upperleg"/>
    <child link="lh_lowerleg"/>
    <axis xyz="0 0 1"/>
    <limit effort="150.0" lower="0.349065850399" upper="2.44346095279" velocity="12.0"/>
    <dynamics damping="0.1" friction="0"/>
    <safety_controller k_position="100" k_velocity="100" soft_lower_limit="-10" soft_upper_limit="12.45"/>
    <!-- Foot joint -->
  </joint>
  <joint name="lh_foot_joint" type="fixed">
    <origin rpy="1.57079632679 0 -1.57079632679" xyz="0.35 0 0"/>
    <parent link="lh_lowerleg"/>
    <child link="lh_foot"/>
  </joint>
  <link name="lh_hipassembly">
    <inertial>
      <origin xyz="0.04263         -0.0         -0.16931"/>
      <mass value="2.93"/>
      <inertia ixx="0.134705" ixy="3.6e-05" ixz="0.022734" iyy="0.144171" iyz="5.1e-05" izz="0.011033"/>
    </inertial>
    <visual>
      <origin rpy="3.14159265359 0 0" xyz="0 0 0"/>
      <geometry>
        <mesh filename="package://hyq_description/meshes/leg/hipassembly.dae" scale="1 1 1"/>
      </geometry>
    </visual>
    <collision>
      <origin rpy="3.14159265359 0 0" xyz="0 0 0"/>
      <geometry>
        <mesh filename="package://hyq_description/meshes/leg/hipassembly.dae" scale="1 1 1"/>
      </geometry>
    </collision>
  </link>
  <link name="lh_upperleg">
    <inertial>
      <origin xyz="0.15074 0.02625 0.0"/>
      <mass value="2.638"/>
      <inertia ixx="0.005495" ixy="0.007418" ixz="0.000102" iyy="0.087136" iyz="-2.1e-05" izz="0.089871"/>
    </inertial>
    <visual>
      <origin rpy="3.14159265359 0 0" xyz="0 0 0"/>
      <geometry>
        <mesh filename="package://hyq_description/meshes/leg/upperleg.dae" scale="1 1 1"/>
      </geometry>
    </visual>
    <collision>
      <origin rpy="3.14159265359 0 0" xyz="0 0 0"/>
      <geometry>
        <mesh filename="package://hyq_description/meshes/leg/upperleg.dae" scale="1 1 1"/>
      </geometry>
    </collision>
  </link>
  <link name="lh_lowerleg">
    <inertial>
      <origin xyz="0.1254 5e-05 -0.0001"/>
      <mass value="0.881"/>
      <inertia ixx="0.000468" ixy="0.0" ixz="0.0" iyy="0.026409" iyz="0.0" izz="0.026181"/>
    </inertial>
    <visual>
      <geometry>
        <mesh filename="package://hyq_description/meshes/leg/lowerleg.dae" scale="1 1 1"/>
      </geometry>
      <material name="white"/>
    </visual>
    <collision>
      <geometry>
        <mesh filename="package://hyq_description/meshes/leg/lowerlegreduced.dae" scale="1 1 1"/>
      </geometry>
    </collision>
  </link>
  <link name="lh_foot">
    <inertial>
      <origin xyz="0 0 0"/>
      <mass value="0.01"/>
      <inertia ixx="0.0" ixy="0.0" ixz="0.0" iyy="0.0" iyz="0.0" izz="0.0"/>
    </inertial>
    <visual>
				<origin xyz="0.0 0.0 0.0" rpy="0.0 0.0 0.0"/>
				<geometry>
					<sphere radius="0.021"/>
				</geometry>
			</visual>
    <collision>
      <origin rpy="0 0 0" xyz="0 0 0"/>
      <geometry>
        <sphere radius="0.02175"/>
      </geometry>
    </collision>
  </link>
  <transmission name="lh_haa_trans">
    <type>transmission_interface/SimpleTransmission</type>
    <joint name="lh_haa_joint">
      <hardwareInterface>EffortJointInterface</hardwareInterface>
    </joint>
    <actuator name="lh_haa_motor">
      <hardwareInterface>EffortJointInterface</hardwareInterface>
      <mechanicalReduction>1</mechanicalReduction>
    </actuator>
  </transmission>
  <transmission name="lh_hfe_upper_trans">
    <type>transmission_interface/SimpleTransmission</type>
    <joint name="lh_hfe_joint">
      <hardwareInterface>EffortJointInterface</hardwareInterface>
    </joint>
    <actuator name="lh_hfe_motor">
      <hardwareInterface>EffortJointInterface</hardwareInterface>
      <mechanicalReduction>1</mechanicalReduction>
    </actuator>
  </transmission>
  <transmission name="lh_kfe_trans">
    <type>transmission_interface/SimpleTransmission</type>
    <joint name="lh_kfe_joint">
      <hardwareInterface>EffortJointInterface</hardwareInterface>
    </joint>
    <actuator name="lh_kfe_motor">
      <hardwareInterface>EffortJointInterface</hardwareInterface>
      <mechanicalReduction>1</mechanicalReduction>
    </actuator>
  </transmission>
  <gazebo reference="lh_lowerleg">
    <kp>1000000.0</kp>
    <kd>100.0</kd>
    <mu1>1.5</mu1>
    <mu2>1.5</mu2>
    <fdir1>1 0 0</fdir1>
    <maxVel>1.0</maxVel>
    <minDepth>0.00</minDepth>
  </gazebo>
  <!-- RH leg -->
  <joint name="rh_haa_joint" type="revolute">
    <origin rpy="0 1.57079632679 0" xyz="-0.3735 -0.207 0"/>
    <parent link="trunk"/>
    <child link="rh_hipassembly"/>
    <axis xyz="0 0 1"/>
    <limit effort="150.0" lower="-1.2217304764" upper="0.523598775598" velocity="12.0"/>
    <dynamics damping="0.1" friction="0"/>
    <safety_controller k_position="100" k_velocity="100" soft_lower_limit="-10" soft_upper_limit="12.45"/>
  </joint>
  <joint name="rh_hfe_joint" type="revolute">
    <origin rpy="-1.57079632679 0 0" xyz="0.082 0 0"/>
    <parent link="rh_hipassembly"/>
    <child link="rh_upperleg"/>
    <axis xyz="0 0 1"/>
    <limit effort="150.0" lower="-1.2217304764" upper="0.872664625997" velocity="12.0"/>
    <dynamics damping="0.1" friction="0"/>
    <safety_controller k_position="100" k_velocity="100" soft_lower_limit="-10" soft_upper_limit="12.45"/>
  </joint>
  <joint name="rh_kfe_joint" type="revolute">
    <origin rpy="0 0 0" xyz="0.35 0 0"/>
    <parent link="rh_upperleg"/>
    <child link="rh_lowerleg"/>
    <axis xyz="0 0 1"/>
    <limit effort="150.0" lower="0.349065850399" upper="2.44346095279" velocity="12.0"/>
    <dynamics damping="0.1" friction="0"/>
    <safety_controller k_position="100" k_velocity="100" soft_lower_limit="-10" soft_upper_limit="12.45"/>
    <!-- Foot joint -->
  </joint>
  <joint name="rh_foot_joint" type="fixed">
    <origin rpy="1.57079632679 0 -1.57079632679" xyz="0.35 0 0"/>
    <parent link="rh_lowerleg"/>
    <child link="rh_foot"/>
  </joint>
  <link name="rh_hipassembly">
    <inertial>
      <origin xyz="0.04263         0.0         0.16931"/>
      <mass value="2.93"/>
      <inertia ixx="0.134705" ixy="-3.6e-05" ixz="-0.022734" iyy="0.144171" iyz="5.1e-05" izz="0.011033"/>
    </inertial>
    <visual>
      <origin rpy="0.0 0 0" xyz="0 0 0"/>
      <geometry>
        <mesh filename="package://hyq_description/meshes/leg/hipassembly.dae" scale="1 1 1"/>
      </geometry>
    </visual>
    <collision>
      <origin rpy="0.0 0 0" xyz="0 0 0"/>
      <geometry>
        <mesh filename="package://hyq_description/meshes/leg/hipassembly.dae" scale="1 1 1"/>
      </geometry>
    </collision>
  </link>
  <link name="rh_upperleg">
    <inertial>
      <origin xyz="0.15074 -0.02625 0.0"/>
      <mass value="2.638"/>
      <inertia ixx="0.005495" ixy="0.007418" ixz="0.000102" iyy="0.087136" iyz="-2.1e-05" izz="0.089871"/>
    </inertial>
    <visual>
      <origin rpy="3.14159265359 0 0" xyz="0 0 0"/>
      <geometry>
        <mesh filename="package://hyq_description/meshes/leg/upperleg.dae" scale="1 1 1"/>
      </geometry>
    </visual>
    <collision>
      <origin rpy="3.14159265359 0 0" xyz="0 0 0"/>
      <geometry>
        <mesh filename="package://hyq_description/meshes/leg/upperleg.dae" scale="1 1 1"/>
      </geometry>
    </collision>
  </link>
  <link name="rh_lowerleg">
    <inertial>
      <origin xyz="0.1254 5e-05 -0.0001"/>
      <mass value="0.881"/>
      <inertia ixx="0.000468" ixy="0.0" ixz="0.0" iyy="0.026409" iyz="0.0" izz="0.026181"/>
    </inertial>
    <visual>
      <geometry>
        <mesh filename="package://hyq_description/meshes/leg/lowerleg.dae" scale="1 1 1"/>
      </geometry>
      <material name="white"/>
    </visual>
    <collision>
      <geometry>
        <mesh filename="package://hyq_description/meshes/leg/lowerlegreduced.dae" scale="1 1 1"/>
      </geometry>
    </collision>
  </link>
  <link name="rh_foot">
    <inertial>
      <origin xyz="0 0 0"/>
      <mass value="0.01"/>
      <inertia ixx="0.0" ixy="0.0" ixz="0.0" iyy="0.0" iyz="0.0" izz="0.0"/>
    </inertial>
    <visual>
				<origin xyz="0.0 0.0 0.0" rpy="0.0 0.0 0.0"/>
				<geometry>
					<sphere radius="0.021"/>
				</geometry>
			</visual>
    <collision>
      <origin rpy="0 0 0" xyz="0 0 0"/>
      <geometry>
        <sphere radius="0.02175"/>
      </geometry>
    </collision>
  </link>
  <transmission name="rh_haa_trans">
    <type>transmission_interface/SimpleTransmission</type>
    <joint name="rh_haa_joint">
      <hardwareInterface>EffortJointInterface</hardwareInterface>
    </joint>
    <actuator name="rh_haa_motor">
      <hardwareInterface>EffortJointInterface</hardwareInterface>
      <mechanicalReduction>1</mechanicalReduction>
    </actuator>
  </transmission>
  <transmission name="rh_hfe_upper_trans">
    <type>transmission_interface/SimpleTransmission</type>
    <joint name="rh_hfe_joint">
      <hardwareInterface>EffortJointInterface</hardwareInterface>
    </joint>
    <actuator name="rh_hfe_motor">
      <hardwareInterface>EffortJointInterface</hardwareInterface>
      <mechanicalReduction>1</mechanicalReduction>
    </actuator>
  </transmission>
  <transmission name="rh_kfe_trans">
    <type>transmission_interface/SimpleTransmission</type>
    <joint name="rh_kfe_joint">
      <hardwareInterface>EffortJointInterface</hardwareInterface>
    </joint>
    <actuator name="rh_kfe_motor">
      <hardwareInterface>EffortJointInterface</hardwareInterface>
      <mechanicalReduction>1</mechanicalReduction>
    </actuator>
  </transmission>
  <gazebo reference="rh_lowerleg">
    <kp>1000000.0</kp>
    <kd>100.0</kd>
    <mu1>1.5</mu1>
    <mu2>1.5</mu2>
    <fdir1>1 0 0</fdir1>
    <maxVel>1.0</maxVel>
    <minDepth>0.00</minDepth>
  </gazebo>
  <!-- IMU trunk -->
  <xacro:microstrain_3dmgx325_imu imu_name="3dmgx325_trunk_imu" imu_topic="trunk_imu/data" parent="trunk" stdev="0.00017" update_rate="100.0">
    <origin rpy="0 -3.14159265359 0" xyz="0.3 0 0.095"/>
  </xacro:microstrain_3dmgx325_imu>
  <!-- Velodyne -->
  <xacro:velodyne name="trunk_mount" parent="trunk">
    <origin rpy="0 0 0" xyz="0.39 0 0.269"/>
  </xacro:velodyne>
  <!-- PTU unit -->
  <xacro:ptu_d46 name="ptu" parent="trunk">
    <origin rpy="-0.013127 0.569257 -0.007748" xyz="0.657353 0.015447 0.119533"/>
    <!--		<origin xyz="0.667353 -0.010101 0.160544" rpy="0.043239 0.569257 0.041771"/>-->
  </xacro:ptu_d46>
  <!-- Asus Xtion Pro -->
  <!--<origin xyz="0 0.005 0.036" rpy="0 0 0"/> with Bumblebee setup -->
  <!--<origin xyz="0 0 0.04397" rpy="0 0 0"/> with Vislab setup -->
  <!--
	<xacro:asus_xtion_camera
		name="head_mount"
		parent="ptu_mount_link">
		<origin xyz="0 0.005 0.036" rpy="0 0 0"/>
	</xacro:asus_xtion_camera>
-->
  <!-- Kinect -->
  <!-- is no more used, but we keep it for compatibilty -->
  <!--xacro:kinect_camera
		name="head_mount"
		parent="trunk">
		<origin xyz="0.63 0 0.095" rpy="0 0 0"/>
	</xacro:kinect_camera-->
  <!-- Bumblebee -->
  <!--
	<xacro:bumblebee_97
		parent_link="ptu_mount_link"
		xyz="0 0 0.018"
		rpy="0 0 0"
		ns="bumblebee"
		frame_prefix="bumblebee_"
		high_res="false"/>
-->
  <!--	<xacro:vislab_3dve_72
		name="vislab_3dve"
		parent="ptu_mount_link"
		xyz="0 0 0.025"
		rpy="0 0 0"
		high_res="false"/>-->
</robot>

